# debianのDockerfile

Pythonセットアップするコマンド。これでnumpyもインストールできる。venvを使っているのは、PEP668対策。
- `apt install python3` だとnumpyやpillowのインストールに失敗するので、代わりに `python3-dev` をインストールする。
- インストール先が `/usr/bin/` になるので、OS標準のPythonとみなされ、 `pip3 install` 時に特殊なオプション( `--break-system-packages` )が必要になる。
- セオリー通り、virtual環境で `pip3 install` する。
```sh
apt update &&\
apt upgrade &&\
apt install -y python3-dev python3-pip python3-venv &&\
python3 -m venv env &&
. env/bin/activate
```
  
# スレッド立たないエラー

```
game_1   | begin_minecraft
game_1   | shutdown called
game_1   | server cancelled gracefully
game_1   | end process
game_1   | Traceback (most recent call last):
game_1   |   File "/runner/run.py", line 521, in <module>
game_1   |     asyncio.run(map_updater(game_dir))
game_1   |   File "/usr/lib/python3.11/asyncio/runners.py", line 190, in run
game_1   |     return runner.run(main)
game_1   |            ^^^^^^^^^^^^^^^^
game_1   |   File "/usr/lib/python3.11/asyncio/runners.py", line 118, in run
game_1   |     return self._loop.run_until_complete(task)
game_1   |            ^^^^^^^^^^^^^^^^^^^^^^^^^^^^^^^^^^^
game_1   |   File "/usr/lib/python3.11/asyncio/base_events.py", line 653, in run_until_complete
game_1   |     return future.result()
game_1   |            ^^^^^^^^^^^^^^^
game_1   |   File "/runner/run.py", line 417, in map_updater
game_1   |     proc_terrain = await asyncio.create_subprocess_shell(
game_1   |                    ^^^^^^^^^^^^^^^^^^^^^^^^^^^^^^^^^^^^^^
game_1   |   File "/usr/lib/python3.11/asyncio/subprocess.py", line 205, in create_subprocess_shell
game_1   |     transport, protocol = await loop.subprocess_shell(
game_1   |                           ^^^^^^^^^^^^^^^^^^^^^^^^^^^^
game_1   |   File "/usr/lib/python3.11/asyncio/base_events.py", line 1661, in subprocess_shell
game_1   |     transport = await self._make_subprocess_transport(
game_1   |                 ^^^^^^^^^^^^^^^^^^^^^^^^^^^^^^^^^^^^^^
game_1   |   File "/usr/lib/python3.11/asyncio/unix_events.py", line 212, in _make_subprocess_transport
game_1   |     watcher.add_child_handler(transp.get_pid(),
game_1   |   File "/usr/lib/python3.11/asyncio/unix_events.py", line 1388, in add_child_handler
game_1   |     thread.start()
game_1   |   File "/usr/lib/python3.11/threading.py", line 957, in start
game_1   |     _start_new_thread(self._bootstrap, ())
game_1   | RuntimeError: can't start new thread
game_1   | Task exception was never retrieved
game_1   | future: <Task finished name='Task-3' coro=<MinecraftServer.run() done, defined at /runner/run.py:184> exception=RuntimeError("can't start new thread")>
game_1   | Traceback (most recent call last):
game_1   |   File "/runner/run.py", line 195, in run
game_1   |     self.process = await asyncio.create_subprocess_shell(
game_1   |                    ^^^^^^^^^^^^^^^^^^^^^^^^^^^^^^^^^^^^^^
game_1   |   File "/usr/lib/python3.11/asyncio/subprocess.py", line 205, in create_subprocess_shell
game_1   |     transport, protocol = await loop.subprocess_shell(
game_1   |                           ^^^^^^^^^^^^^^^^^^^^^^^^^^^^
game_1   |   File "/usr/lib/python3.11/asyncio/base_events.py", line 1661, in subprocess_shell
game_1   |     transport = await self._make_subprocess_transport(
game_1   |                 ^^^^^^^^^^^^^^^^^^^^^^^^^^^^^^^^^^^^^^
game_1   |   File "/usr/lib/python3.11/asyncio/unix_events.py", line 212, in _make_subprocess_transport
game_1   |     watcher.add_child_handler(transp.get_pid(),
game_1   |   File "/usr/lib/python3.11/asyncio/unix_events.py", line 1388, in add_child_handler
game_1   |     thread.start()
game_1   |   File "/usr/lib/python3.11/threading.py", line 957, in start
game_1   |     _start_new_thread(self._bootstrap, ())
game_1   | RuntimeError: can't start new thread
game_1   | Future exception was never retrieved
game_1   | future: <Future finished exception=CancelledError()>
game_1   | Traceback (most recent call last):
game_1   |   File "/usr/lib/python3.11/asyncio/base_subprocess.py", line 168, in _connect_pipes
game_1   |     _, pipe = await loop.connect_read_pipe(
game_1   |               ^^^^^^^^^^^^^^^^^^^^^^^^^^^^^
game_1   |   File "/usr/lib/python3.11/asyncio/base_events.py", line 1592, in connect_read_pipe
game_1   |     await waiter
game_1   | asyncio.exceptions.CancelledError
game_1   | Future exception was never retrieved
game_1   | future: <Future finished exception=CancelledError()>
game_1   | Traceback (most recent call last):
game_1   |   File "/runner/run.py", line 521, in <module>
game_1   |     asyncio.run(map_updater(game_dir))
game_1   |   File "/usr/lib/python3.11/asyncio/runners.py", line 190, in run
game_1   |     return runner.run(main)
game_1   |            ^^^^^^^^^^^^^^^^
game_1   |   File "/usr/lib/python3.11/asyncio/runners.py", line 118, in run
game_1   |     return self._loop.run_until_complete(task)
game_1   |            ^^^^^^^^^^^^^^^^^^^^^^^^^^^^^^^^^^^
game_1   |   File "/usr/lib/python3.11/asyncio/base_events.py", line 653, in run_until_complete
game_1   |     return future.result()
game_1   |            ^^^^^^^^^^^^^^^
game_1   |   File "/runner/run.py", line 417, in map_updater
game_1   |     proc_terrain = await asyncio.create_subprocess_shell(
game_1   |                    ^^^^^^^^^^^^^^^^^^^^^^^^^^^^^^^^^^^^^^
game_1   |   File "/usr/lib/python3.11/asyncio/subprocess.py", line 205, in create_subprocess_shell
game_1   |     transport, protocol = await loop.subprocess_shell(
game_1   |                           ^^^^^^^^^^^^^^^^^^^^^^^^^^^^
game_1   |   File "/usr/lib/python3.11/asyncio/base_events.py", line 1661, in subprocess_shell
game_1   |     transport = await self._make_subprocess_transport(
game_1   |                 ^^^^^^^^^^^^^^^^^^^^^^^^^^^^^^^^^^^^^^
game_1   |   File "/usr/lib/python3.11/asyncio/unix_events.py", line 212, in _make_subprocess_transport
game_1   |     watcher.add_child_handler(transp.get_pid(),
game_1   |   File "/usr/lib/python3.11/asyncio/unix_events.py", line 1388, in add_child_handler
game_1   |     thread.start()
game_1   |   File "/usr/lib/python3.11/threading.py", line 957, in start
game_1   |     _start_new_thread(self._bootstrap, ())
game_1   | RuntimeError: can't start new thread
game_1   | 
game_1   | During handling of the above exception, another exception occurred:
game_1   | 
game_1   | Traceback (most recent call last):
game_1   |   File "/usr/lib/python3.11/asyncio/base_subprocess.py", line 162, in _connect_pipes
game_1   |     _, pipe = await loop.connect_write_pipe(
game_1   |               ^^^^^^^^^^^^^^^^^^^^^^^^^^^^^^
game_1   |   File "/usr/lib/python3.11/asyncio/base_events.py", line 1608, in connect_write_pipe
game_1   |     await waiter
game_1   | asyncio.exceptions.CancelledError
sohei_game_1 exited with code 1
```
